<?xml version="1.0" ?>
<!-- =================================================================================== -->
<!-- |    This document was autogenerated by xacro from /opt/ros/noetic/share/mira_picker/urdf/mira_picker.urdf.xacro | -->
<!-- |    EDITING THIS FILE BY HAND IS NOT RECOMMENDED                                 | -->
<!-- =================================================================================== -->
<robot name="mira" xmlns:controller="http://playerstage.sourceforge.net/gazebo/xmlschema/#controller" xmlns:interface="http://playerstage.sourceforge.net/gazebo/xmlschema/#interface" xmlns:sensor="http://playerstage.sourceforge.net/gazebo/xmlschema/#sensor">
  <!-- Includes -->
  <material name="aluminum">
    <color rgba="0.5 0.5 0.5 1"/>
  </material>
  <!-- Encoder offsets are not included here but set in a separate config file -->
  <material name="blue">
    <color rgba="0 0 0.8 1"/>
  </material>
  <material name="white">
    <color rgba="1 1 1 1"/>
  </material>
  <material name="MelonYellow">
    <color rgba="1.0 0.6 0.0 1.0"/>
  </material>
  <link name="root_link">
		</link>
  <joint name="root_joint" type="fixed">
    <!-- joint1 base_to_right_leg 0.2945 -->
    <origin rpy="0 0 1.5708" xyz="0 0 0.0"/>
    <axis xyz="0 0 1"/>
    <parent link="root_link"/>
    <child link="base_link"/>
  </joint>
  <link name="base_link">
    <!-- link0 -->
    <inertial>
      <mass value="9.02994035"/>
      <origin rpy="0 0 0" xyz="-0.00864914 0.00066084 0.09191042"/>
      <!-- did not chenge inertia values -->
      <inertia ixx="0.04871169" ixy="0.00072792" ixz="-0.00354042" iyy="0.06082174" iyz="0.00036285" izz="0.06803946"/>
    </inertial>
    <visual>
      <origin rpy="0 0 0" xyz="0 0 0"/>
      <geometry>
        <mesh filename="package://mira_description/meshes/mira/Link0.stl"/>
      </geometry>
      <material name="blue"/>
    </visual>
    <collision>
      <origin rpy="0 0 0" xyz="0 0 0"/>
      <geometry>
        <mesh filename="package://mira_description/meshes/collision/Link0.stl"/>
      </geometry>
      <material name="blue"/>
    </collision>
  </link>
  <link name="link1">
    <!-- link1 right_leg-->
    <inertial>
      <mass value="8.81388995"/>
      <origin rpy="0 0 0" xyz="0.00009227 0.01727770 -0.09151695"/>
      <inertia ixx="0.11695855" ixy="-0.00006599" ixz="-0.00007443" iyy="0.09523956" iyz="-0.01391589" izz="0.05142057"/>
    </inertial>
    <visual>
      <origin rpy="0 0 0" xyz="0 0 0"/>
      <geometry>
        <mesh filename="package://mira_description/meshes/mira/Link1.stl"/>
      </geometry>
      <material name="white"/>
    </visual>
    <collision>
      <origin rpy="0 0 0" xyz="0 0 0"/>
      <geometry>
        <mesh filename="package://mira_description/meshes/collision/Link1.stl"/>
      </geometry>
      <material name="white"/>
    </collision>
  </link>
  <joint name="joint1" type="revolute">
    <!-- joint1 base_to_right_leg 0.2945 -->
    <origin rpy="0 0 -1.5708" xyz="0 0 0.352"/>
    <axis xyz="0 0 1"/>
    <limit effort="1260" lower="-3.14159" upper="3.14159" velocity="7.60"/>
    <parent link="base_link"/>
    <child link="link1"/>
  </joint>
  <link name="link2">
    <!-- link2 right_base -->
    <inertial>
      <mass value="10.73876455"/>
      <origin rpy="0 0 0" xyz="0.00005095 -0.02980593 0.00384129"/>
      <inertia ixx="0.08469338" ixy="-0.00000976" ixz="0.00000284" iyy="0.04466526" iyz="-0.00106970" izz="0.08929344"/>
    </inertial>
    <visual>
      <origin rpy="0 0 0" xyz="0 0 0"/>
      <geometry>
        <mesh filename="package://mira_description/meshes/mira/Link2.stl"/>
      </geometry>
      <material name="blue"/>
    </visual>
    <collision>
      <origin rpy="0 0 0" xyz="0 0 0"/>
      <geometry>
        <mesh filename="package://mira_description/meshes/collision/Link2.stl"/>
      </geometry>
      <material name="blue"/>
    </collision>
  </link>
  <joint name="joint2" type="revolute">
    <!-- joint2 right_base_joint -->
    <origin rpy="-1.5708 0 0" xyz="0 0 0"/>
    <!-- or: 0 -1.5708 1.5708 or: 1.5708 -1.5708 0 up: -1.5708 0 0-->
    <axis xyz="0 0 1"/>
    <limit effort="710" lower="-2.11" upper="2.11" velocity="7.16"/>
    <!--<safety_controller k_position="100" k_velocity="2" soft_lower_limit="-2.105948851735" soft_upper_limit="2.105948851735" />-->
    <dynamics damping="13.0" friction="9.0"/>
    <parent link="link1"/>
    <child link="link2"/>
  </joint>
  <link name="link3">
    <!-- link3 right_front_wheel -->
    <inertial>
      <mass value="7.80048461"/>
      <origin rpy="0 0 0" xyz="0.00000508 -0.01311256 -0.29310398"/>
      <inertia ixx="0.37362453" ixy="-0.00000061" ixz="-0.00001502" iyy="0.36314616" iyz="0.02636093" izz="0.02643739"/>
    </inertial>
    <visual>
      <origin rpy="0 0 0" xyz="0 0 0"/>
      <geometry>
        <mesh filename="package://mira_description/meshes/mira/Link3.stl"/>
      </geometry>
      <material name="white"/>
    </visual>
    <collision>
      <origin rpy="0 0 0" xyz="0 0 0"/>
      <geometry>
        <mesh filename="package://mira_description/meshes/collision/Link3.stl"/>
      </geometry>
      <material name="white"/>
    </collision>
  </link>
  <joint name="joint3" type="revolute">
    <!-- joint3 right_front_wheel_joint -->
    <origin rpy="1.5708 0 0" xyz="0 -0.7 0"/>
    <!-- thin left: 1.5708 3.1416 0  -->
    <axis xyz="0 0 1"/>
    <limit effort="380" lower="-3.14159" upper="3.14159" velocity="9.43"/>
    <!--<safety_controller k_position="100" k_velocity="2" soft_lower_limit="-3.05948851735" soft_upper_limit="3.05948851735" />-->
    <dynamics damping="10.0" friction="4.5"/>
    <parent link="link2"/>
    <child link="link3"/>
  </joint>
  <link name="link4">
    <!-- link4 right_back_wheel -->
    <inertial>
      <mass value="4.90782352"/>
      <origin rpy="0 0 0" xyz="0.00000273   -0.02342897   -0.00561818"/>
      <inertia ixx="0.02108339" ixy="-0.00000071" ixz="-0.00000036" iyy="0.01108371" iyz="0.00064263" izz="0.02077348"/>
    </inertial>
    <visual>
      <origin rpy="0 0 0" xyz="0 0 0"/>
      <geometry>
        <mesh filename="package://mira_description/meshes/mira/Link4.stl"/>
      </geometry>
      <material name="blue"/>
    </visual>
    <collision>
      <origin rpy="0 0 0" xyz="0 0 0"/>
      <geometry>
        <mesh filename="package://mira_description/meshes/collision/Link4.stl"/>
      </geometry>
      <material name="blue"/>
    </collision>
  </link>
  <joint name="joint4" type="revolute">
    <!-- joint4 right_back_wheel_joint -->
    <origin rpy="-1.5708 0 0" xyz="0 0 0"/>
    <axis xyz="0 0 1"/>
    <limit effort="70" lower="-2.35" upper="2.35" velocity="17.4"/>
    <!--<safety_controller k_position="100" k_velocity="2" soft_lower_limit="-2.55948851735" soft_upper_limit="2.55948851735" />-->
    <dynamics damping="2.5" friction="4.0"/>
    <parent link="link3"/>
    <child link="link4"/>
  </joint>
  <link name="link5">
    <!-- link5 left_leg -->
    <inertial>
      <mass value="5.89239887"/>
      <origin rpy="0 0 0" xyz="0.00003764   0.05360461   -0.27051890"/>
      <inertia ixx="0.34526601" ixy="-0.00001006" ixz="-0.00004889" iyy="0.33395748" iyz="-0.06425872" izz="0.02387784"/>
    </inertial>
    <visual>
      <origin rpy="0 0 0" xyz="0 0 0"/>
      <geometry>
        <mesh filename="package://mira_description/meshes/mira/Link5.stl"/>
      </geometry>
      <material name="white"/>
    </visual>
    <collision>
      <origin rpy="0 0 0" xyz="0 0 0"/>
      <geometry>
        <mesh filename="package://mira_description/meshes/collision/Link5.stl"/>
      </geometry>
      <material name="white"/>
      <!-- 
				<origin rpy="0 0 0" xyz="0 0 -0.23" />
				<geometry>
					<cylinder length="0.46" radius="0.115" />
				</geometry> -->
    </collision>
  </link>
  <joint name="joint5" type="revolute">
    <!-- joint5 base_to_left_leg -0.65 -->
    <origin rpy="1.5708 3.14159 0" xyz="0 -0.7 0"/>
    <axis xyz="0 0 1"/>
    <limit effort="80" lower="-3.14159" upper="3.14159" velocity="18.6"/>
    <!--<safety_controller k_position="100" k_velocity="2" soft_lower_limit="-2.55948851735" soft_upper_limit="2.55948851735" />-->
    <dynamics damping="5.0" friction="4.0"/>
    <parent link="link4"/>
    <child link="link5"/>
  </joint>
  <link name="link6">
    <!-- link6 left_base -->
    <inertial>
      <mass value="2.76974945"/>
      <origin rpy="0 0 0" xyz="0.00007333   0.01105196   0.02462915"/>
      <inertia ixx="0.00955946" ixy="-0.00001486" ixz="0.00000146" iyy="0.00723805" iyz="0.00066557" izz="0.00641809"/>
    </inertial>
    <visual>
      <origin rpy="0 0 0" xyz="0 0 0"/>
      <geometry>
        <mesh filename="package://mira_description/meshes/mira/Link6.stl"/>
      </geometry>
      <material name="blue"/>
    </visual>
    <collision>
      <origin rpy="0 0 0" xyz="0 0 0"/>
      <geometry>
        <mesh filename="package://mira_description/meshes/collision/Link6.stl"/>
      </geometry>
      <material name="blue"/>
    </collision>
  </link>
  <joint name="joint6" type="revolute">
    <!-- joint6 -->
    <origin rpy="-1.5708 0 0" xyz="0 0 0"/>
    <axis xyz="0 0 1"/>
    <limit effort="21" lower="-3.14159" upper="3.14159" velocity="25.3"/>
    <!--<safety_controller k_position="100" k_velocity="2" soft_lower_limit="-4.0" soft_upper_limit="4.0" />-->
    <dynamics damping="1.25" friction="1.25"/>
    <parent link="link5"/>
    <child link="link6"/>
  </joint>
  <link name="link7">
    <inertial>
      <mass value="1.19341401"/>
      <origin rpy="0 0 0" xyz="-0.00006102   0.00027280   0.04324279"/>
      <inertia ixx="0.00254735" ixy="-0.00000278" ixz="-0.00000158" iyy="0.00255260" iyz="-0.00000991" izz="0.00099944"/>
    </inertial>
    <visual>
      <origin rpy="0 0 0" xyz="0 0 0"/>
      <geometry>
        <mesh filename="package://mira_description/meshes/mira/Link7.stl"/>
      </geometry>
    </visual>
    <collision>
      <origin rpy="0 0 0" xyz="0 0 0"/>
      <geometry>
        <mesh filename="package://mira_description/meshes/collision/Link7.stl"/>
      </geometry>
    </collision>
  </link>
  <joint name="joint7" type="revolute">
    <!-- joint7 -->
    <origin rpy="1.5708 0 0" xyz="0 0 0"/>
    <axis xyz="0 0 1"/>
    <limit effort="10" lower="-3.14159" upper="3.14159" velocity="10"/>
    <!--<safety_controller k_position="10" k_velocity="1" soft_lower_limit="-4.0" soft_upper_limit="4.0" />-->
    <dynamics damping="2" friction="2"/>
    <parent link="link6"/>
    <child link="link7"/>
  </joint>
  <link name="tool0"/>
  <joint name="link7_to_tool0" type="fixed">
    <!-- joint7 -->
    <origin rpy="0 0 0" xyz="0 0 0.10"/>
    <parent link="link7"/>
    <child link="tool0"/>
  </joint>
  <link name="flange"/>
  <joint name="link7_to_flange" type="fixed">
    <!-- joint7 -->
    <origin rpy="0 0 0" xyz="0 0 0.10"/>
    <parent link="link7"/>
    <child link="flange"/>
  </joint>
  <link name="ee_link"/>
  <joint name="flange_to_ee_link" type="fixed">
    <!-- joint7 -->
    <origin rpy="0 0 0" xyz="0 0 0.0"/>
    <parent link="flange"/>
    <child link="ee_link"/>
  </joint>
  <link name="camera_calibration_link"/>
  <joint name="camera_calibration_joint" type="fixed">
    <origin rpy="-1.5708 -1.5708 0.0 " xyz="0.02 0.01 -0.04"/>
    <parent link="link6"/>
    <child link="camera_calibration_link"/>
  </joint>
  <!-- Base cameras -->
  <link name="base_camera_1_parent_link"/>
  <joint name="base_link_to_base_camera1_parent_link" type="fixed">
    <origin rpy="0.0 0.0 -0.5074274" xyz=" 0.13019 -0.011751 0.037583 "/>
    <parent link="base_link"/>
    <child link="base_camera_1_parent_link"/>
  </joint>
  <!-- camera body, with origin at bottom screw mount -->
  <joint name="base_camera_1_joint" type="fixed">
    <origin rpy="0 -0.5162342 0" xyz="0 0 0"/>
    <parent link="base_camera_1_parent_link"/>
    <child link="base_camera_1_bottom_screw_frame"/>
  </joint>
  <link name="base_camera_1_bottom_screw_frame"/>
  <joint name="base_camera_1_link_joint" type="fixed">
    <origin rpy="0 0 0" xyz="0 0.02 0.0115"/>
    <parent link="base_camera_1_bottom_screw_frame"/>
    <child link="base_camera_1_link"/>
  </joint>
  <link name="base_camera_1_link">
    <visual>
      <origin rpy="1.5707963267948966 0 1.5707963267948966" xyz="0.00987 -0.02 0"/>
      <geometry>
        <!-- <box size="${d415_cam_width} ${d415_cam_height} ${d415_cam_depth}"/> -->
        <mesh filename="package://realsense2_description/meshes/d415.stl"/>
      </geometry>
      <material name="aluminum"/>
    </visual>
    <collision>
      <origin rpy="0 0 0" xyz="0 -0.02 0"/>
      <geometry>
        <box size="0.02005 0.099 0.023"/>
      </geometry>
    </collision>
    <inertial>
      <!-- The following are not reliable values, and should not be used for modeling -->
      <mass value="0.564"/>
      <origin xyz="0 0 0"/>
      <inertia ixx="0.003881243" ixy="0.0" ixz="0.0" iyy="0.000498940" iyz="0.0" izz="0.003879257"/>
    </inertial>
  </link>
  <!-- camera depth joints and links -->
  <joint name="base_camera_1_depth_joint" type="fixed">
    <origin rpy="0 0 0" xyz="0 0 0"/>
    <parent link="base_camera_1_link"/>
    <child link="base_camera_1_depth_frame"/>
  </joint>
  <link name="base_camera_1_depth_frame"/>
  <joint name="base_camera_1_depth_optical_joint" type="fixed">
    <origin rpy="-1.5707963267948966 0 -1.5707963267948966" xyz="0 0 0"/>
    <parent link="base_camera_1_depth_frame"/>
    <child link="base_camera_1_depth_optical_frame"/>
  </joint>
  <link name="base_camera_1_depth_optical_frame"/>
  <!-- camera left IR joints and links -->
  <joint name="base_camera_1_infra1_joint" type="fixed">
    <origin rpy="0 0 0" xyz="0 0.0 0"/>
    <parent link="base_camera_1_link"/>
    <child link="base_camera_1_infra1_frame"/>
  </joint>
  <link name="base_camera_1_infra1_frame"/>
  <joint name="base_camera_1_infra1_optical_joint" type="fixed">
    <origin rpy="-1.5707963267948966 0 -1.5707963267948966" xyz="0 0 0"/>
    <parent link="base_camera_1_infra1_frame"/>
    <child link="base_camera_1_infra1_optical_frame"/>
  </joint>
  <link name="base_camera_1_infra1_optical_frame"/>
  <!-- camera right IR joints and links -->
  <joint name="base_camera_1_infra2_joint" type="fixed">
    <origin rpy="0 0 0" xyz="0 -0.055 0"/>
    <parent link="base_camera_1_link"/>
    <child link="base_camera_1_infra2_frame"/>
  </joint>
  <link name="base_camera_1_infra2_frame"/>
  <joint name="base_camera_1_infra2_optical_joint" type="fixed">
    <origin rpy="-1.5707963267948966 0 -1.5707963267948966" xyz="0 0 0"/>
    <parent link="base_camera_1_infra2_frame"/>
    <child link="base_camera_1_infra2_optical_frame"/>
  </joint>
  <link name="base_camera_1_infra2_optical_frame"/>
  <!-- camera color joints and links -->
  <joint name="base_camera_1_color_joint" type="fixed">
    <origin rpy="0 0 0" xyz="0 0.015 0"/>
    <parent link="base_camera_1_link"/>
    <child link="base_camera_1_color_frame"/>
  </joint>
  <link name="base_camera_1_color_frame"/>
  <joint name="base_camera_1_color_optical_joint" type="fixed">
    <origin rpy="-1.5707963267948966 0 -1.5707963267948966" xyz="0 0 0"/>
    <parent link="base_camera_1_color_frame"/>
    <child link="base_camera_1_color_optical_frame"/>
  </joint>
  <link name="base_camera_1_color_optical_frame"/>
  <link name="base_camera_2_parent_link"/>
  <joint name="base_link_to_base_camera_2_parent_link" type="fixed">
    <origin rpy="0.0 0.0 -1.5707713" xyz=" 0.000 -0.117921 0.037837 "/>
    <parent link="base_link"/>
    <child link="base_camera_2_parent_link"/>
  </joint>
  <!-- camera body, with origin at bottom screw mount -->
  <joint name="base_camera_2_joint" type="fixed">
    <origin rpy="0 -0.5759183 0" xyz="0 0 0 "/>
    <parent link="base_camera_2_parent_link"/>
    <child link="base_camera_2_bottom_screw_frame"/>
  </joint>
  <link name="base_camera_2_bottom_screw_frame"/>
  <joint name="base_camera_2_link_joint" type="fixed">
    <origin rpy="0 0 0" xyz="0 0.02 0.0115"/>
    <parent link="base_camera_2_bottom_screw_frame"/>
    <child link="base_camera_2_link"/>
  </joint>
  <link name="base_camera_2_link">
    <visual>
      <origin rpy="1.5707963267948966 0 1.5707963267948966" xyz="0.00987 -0.02 0"/>
      <geometry>
        <!-- <box size="${d415_cam_width} ${d415_cam_height} ${d415_cam_depth}"/> -->
        <mesh filename="package://realsense2_description/meshes/d415.stl"/>
      </geometry>
      <material name="aluminum"/>
    </visual>
    <collision>
      <origin rpy="0 0 0" xyz="0 -0.02 0"/>
      <geometry>
        <box size="0.02005 0.099 0.023"/>
      </geometry>
    </collision>
    <inertial>
      <!-- The following are not reliable values, and should not be used for modeling -->
      <mass value="0.564"/>
      <origin xyz="0 0 0"/>
      <inertia ixx="0.003881243" ixy="0.0" ixz="0.0" iyy="0.000498940" iyz="0.0" izz="0.003879257"/>
    </inertial>
  </link>
  <!-- camera depth joints and links -->
  <joint name="base_camera_2_depth_joint" type="fixed">
    <origin rpy="0 0 0" xyz="0 0 0"/>
    <parent link="base_camera_2_link"/>
    <child link="base_camera_2_depth_frame"/>
  </joint>
  <link name="base_camera_2_depth_frame"/>
  <joint name="base_camera_2_depth_optical_joint" type="fixed">
    <origin rpy="-1.5707963267948966 0 -1.5707963267948966" xyz="0 0 0"/>
    <parent link="base_camera_2_depth_frame"/>
    <child link="base_camera_2_depth_optical_frame"/>
  </joint>
  <link name="base_camera_2_depth_optical_frame"/>
  <!-- camera left IR joints and links -->
  <joint name="base_camera_2_infra1_joint" type="fixed">
    <origin rpy="0 0 0" xyz="0 0.0 0"/>
    <parent link="base_camera_2_link"/>
    <child link="base_camera_2_infra1_frame"/>
  </joint>
  <link name="base_camera_2_infra1_frame"/>
  <joint name="base_camera_2_infra1_optical_joint" type="fixed">
    <origin rpy="-1.5707963267948966 0 -1.5707963267948966" xyz="0 0 0"/>
    <parent link="base_camera_2_infra1_frame"/>
    <child link="base_camera_2_infra1_optical_frame"/>
  </joint>
  <link name="base_camera_2_infra1_optical_frame"/>
  <!-- camera right IR joints and links -->
  <joint name="base_camera_2_infra2_joint" type="fixed">
    <origin rpy="0 0 0" xyz="0 -0.055 0"/>
    <parent link="base_camera_2_link"/>
    <child link="base_camera_2_infra2_frame"/>
  </joint>
  <link name="base_camera_2_infra2_frame"/>
  <joint name="base_camera_2_infra2_optical_joint" type="fixed">
    <origin rpy="-1.5707963267948966 0 -1.5707963267948966" xyz="0 0 0"/>
    <parent link="base_camera_2_infra2_frame"/>
    <child link="base_camera_2_infra2_optical_frame"/>
  </joint>
  <link name="base_camera_2_infra2_optical_frame"/>
  <!-- camera color joints and links -->
  <joint name="base_camera_2_color_joint" type="fixed">
    <origin rpy="0 0 0" xyz="0 0.015 0"/>
    <parent link="base_camera_2_link"/>
    <child link="base_camera_2_color_frame"/>
  </joint>
  <link name="base_camera_2_color_frame"/>
  <joint name="base_camera_2_color_optical_joint" type="fixed">
    <origin rpy="-1.5707963267948966 0 -1.5707963267948966" xyz="0 0 0"/>
    <parent link="base_camera_2_color_frame"/>
    <child link="base_camera_2_color_optical_frame"/>
  </joint>
  <link name="base_camera_2_color_optical_frame"/>
  <!-- camera body, with origin at bottom screw mount -->
  <joint name="base_camera_3_joint" type="fixed">
    <origin rpy="3.1415759 -0.5760 -2.7051773" xyz="-0.117849 -0.005996 0.058549"/>
    <parent link="base_link"/>
    <child link="base_camera_3_bottom_screw_frame"/>
  </joint>
  <link name="base_camera_3_bottom_screw_frame"/>
  <joint name="base_camera_3_link_joint" type="fixed">
    <origin rpy="0 0 0" xyz="0 0.02 0.0115"/>
    <parent link="base_camera_3_bottom_screw_frame"/>
    <child link="base_camera_3_link"/>
  </joint>
  <link name="base_camera_3_link">
    <visual>
      <origin rpy="1.5707963267948966 0 1.5707963267948966" xyz="0.00987 -0.02 0"/>
      <geometry>
        <!-- <box size="${d415_cam_width} ${d415_cam_height} ${d415_cam_depth}"/> -->
        <mesh filename="package://realsense2_description/meshes/d415.stl"/>
      </geometry>
      <material name="aluminum"/>
    </visual>
    <collision>
      <origin rpy="0 0 0" xyz="0 -0.02 0"/>
      <geometry>
        <box size="0.02005 0.099 0.023"/>
      </geometry>
    </collision>
    <inertial>
      <!-- The following are not reliable values, and should not be used for modeling -->
      <mass value="0.564"/>
      <origin xyz="0 0 0"/>
      <inertia ixx="0.003881243" ixy="0.0" ixz="0.0" iyy="0.000498940" iyz="0.0" izz="0.003879257"/>
    </inertial>
  </link>
  <!-- camera depth joints and links -->
  <joint name="base_camera_3_depth_joint" type="fixed">
    <origin rpy="0 0 0" xyz="0 0 0"/>
    <parent link="base_camera_3_link"/>
    <child link="base_camera_3_depth_frame"/>
  </joint>
  <link name="base_camera_3_depth_frame"/>
  <joint name="base_camera_3_depth_optical_joint" type="fixed">
    <origin rpy="-1.5707963267948966 0 -1.5707963267948966" xyz="0 0 0"/>
    <parent link="base_camera_3_depth_frame"/>
    <child link="base_camera_3_depth_optical_frame"/>
  </joint>
  <link name="base_camera_3_depth_optical_frame"/>
  <!-- camera left IR joints and links -->
  <joint name="base_camera_3_infra1_joint" type="fixed">
    <origin rpy="0 0 0" xyz="0 0.0 0"/>
    <parent link="base_camera_3_link"/>
    <child link="base_camera_3_infra1_frame"/>
  </joint>
  <link name="base_camera_3_infra1_frame"/>
  <joint name="base_camera_3_infra1_optical_joint" type="fixed">
    <origin rpy="-1.5707963267948966 0 -1.5707963267948966" xyz="0 0 0"/>
    <parent link="base_camera_3_infra1_frame"/>
    <child link="base_camera_3_infra1_optical_frame"/>
  </joint>
  <link name="base_camera_3_infra1_optical_frame"/>
  <!-- camera right IR joints and links -->
  <joint name="base_camera_3_infra2_joint" type="fixed">
    <origin rpy="0 0 0" xyz="0 -0.055 0"/>
    <parent link="base_camera_3_link"/>
    <child link="base_camera_3_infra2_frame"/>
  </joint>
  <link name="base_camera_3_infra2_frame"/>
  <joint name="base_camera_3_infra2_optical_joint" type="fixed">
    <origin rpy="-1.5707963267948966 0 -1.5707963267948966" xyz="0 0 0"/>
    <parent link="base_camera_3_infra2_frame"/>
    <child link="base_camera_3_infra2_optical_frame"/>
  </joint>
  <link name="base_camera_3_infra2_optical_frame"/>
  <!-- camera color joints and links -->
  <joint name="base_camera_3_color_joint" type="fixed">
    <origin rpy="0 0 0" xyz="0 0.015 0"/>
    <parent link="base_camera_3_link"/>
    <child link="base_camera_3_color_frame"/>
  </joint>
  <link name="base_camera_3_color_frame"/>
  <joint name="base_camera_3_color_optical_joint" type="fixed">
    <origin rpy="-1.5707963267948966 0 -1.5707963267948966" xyz="0 0 0"/>
    <parent link="base_camera_3_color_frame"/>
    <child link="base_camera_3_color_optical_frame"/>
  </joint>
  <link name="base_camera_3_color_optical_frame"/>
  <link name="base_camera_3_color_optical_frame_rotated"/>
  <joint name="base_camera_3_rotation_joint" type="fixed">
    <origin rpy="0.0 0.0 3.14159" xyz="0.0 0.0 0.0"/>
    <parent link="base_camera_3_color_optical_frame"/>
    <child link="base_camera_3_color_optical_frame_rotated"/>
  </joint>
  <!-- Radar -->
  <link name="radar_link"/>
  <joint name="base_link_to_radar_link_joint" type="fixed">
    <origin rpy="0.0 0.0 2.356" xyz="-0.07 -0.1 0.05"/>
    <parent link="base_link"/>
    <child link="radar_link"/>
  </joint>
  <!-- <xacro:robotiq_arg2f_85 prefix="${prefix}"/>
        <joint name="${prefix}flange_to_gripper" type="fixed">
            <origin rpy="0 0 1.0472" xyz="0 0 0.0"/>
            <parent link="${prefix}flange"/>
            <child link="${prefix}robotiq_arg2f_base_link"/>
        </joint>

        <link name="${prefix}gripper_tcp">
        </link>
        <joint name="${prefix}gripper_tcp_joint" type="fixed">
            <origin rpy="0 0 0" xyz="0 0 0.166"/>
            <parent link="${prefix}ee_link"/>
            <child link="${prefix}gripper_tcp"/>
        </joint>  -->
  <link name="gripper_tcp">
        </link>
  <joint name="gripper_tcp_joint" type="fixed">
    <origin rpy="0 0 -0.523599" xyz="0 0 0.166"/>
    <parent link="ee_link"/>
    <child link="gripper_tcp"/>
  </joint>
  <link name="table_calibration">
    <visual>
      <origin rpy="0 0 0" xyz="0 0 0"/>
      <geometry>
        <mesh filename="package://mira_picker/meshes/table/visual/table_calibration.stl"/>
      </geometry>
      <material name="white"/>
    </visual>
    <!-- <collision>
                <origin rpy="0 0 0" xyz="0 0 0"/>
                <geometry>
                    <mesh filename="package://mira_picker/meshes/table/collision/table_calibration.stl"/>
                </geometry>
            </collision> -->
  </link>
  <link name="world"/>
  <joint name="world_joint" type="fixed">
    <parent link="world"/>
    <child link="root_link"/>
    <origin rpy="0.0 0.0 0.0" xyz="0.0 0.0 0.391"/>
  </joint>
  <joint name="baselink_table" type="fixed">
    <origin rpy="0 0 0.0" xyz="0 0 -0.310"/>
    <parent link="root_link"/>
    <child link="table_calibration"/>
  </joint>
  <link name="threejs_link"/>
  <joint name="threejs_joint" type="fixed">
    <parent link="world"/>
    <child link="threejs_link"/>
    <origin rpy="1.5708 0.0 0.0" xyz="0.0 0.0 0.391"/>
  </joint>
  <link name="robotiq_arg2f_base_link">
    <inertial>
      <origin rpy="0 0 0" xyz="8.625E-08 -4.6583E-06 0.03145"/>
      <mass value="0.22652"/>
      <inertia ixx="0.00020005" ixy="-4.2442E-10" ixz="-2.9069E-10" iyy="0.00017832" iyz="-3.4402E-08" izz="0.00013478"/>
    </inertial>
    <visual>
      <origin rpy="0 0 0" xyz="0 0 0"/>
      <geometry>
        <mesh filename="package://robotiq_2f_85_gripper_visualization/meshes/visual/robotiq_arg2f_85_base_link.stl" scale="1 1 1"/>
      </geometry>
      <material name="">
        <color rgba="0.1 0.1 0.1 1"/>
      </material>
    </visual>
    <collision>
      <origin rpy="0 0 0" xyz="0 0 0"/>
      <geometry>
        <mesh filename="package://robotiq_2f_85_gripper_visualization/meshes/collision/robotiq_arg2f_base_link.stl"/>
      </geometry>
    </collision>
  </link>
  <link name="left_outer_knuckle">
    <inertial>
      <origin rpy="0 0 0" xyz="-0.000200000000003065 0.0199435877845359 0.0292245259211331"/>
      <mass value="0.00853198276973456"/>
      <inertia ixx="2.89328108496468E-06" ixy="-1.57935047237397E-19" ixz="-1.93980378593255E-19" iyy="1.86719750325683E-06" iyz="-1.21858577871576E-06" izz="1.21905238907251E-06"/>
    </inertial>
    <visual>
      <origin rpy="0 0 0" xyz="0 0 0"/>
      <geometry>
        <mesh filename="package://robotiq_2f_85_gripper_visualization/meshes/visual/robotiq_arg2f_85_outer_knuckle.dae" scale="0.001 0.001 0.001"/>
      </geometry>
      <material name="">
        <color rgba="0.792156862745098 0.819607843137255 0.933333333333333 1"/>
      </material>
    </visual>
    <collision>
      <origin rpy="0 0 0" xyz="0 0 0"/>
      <geometry>
        <mesh filename="package://robotiq_2f_85_gripper_visualization/meshes/collision/robotiq_arg2f_85_outer_knuckle.dae" scale="0.001 0.001 0.001"/>
      </geometry>
    </collision>
  </link>
  <link name="left_outer_finger">
    <inertial>
      <origin rpy="0 0 0" xyz="0.00030115855001899 0.0373907951953854 -0.0208027427000385"/>
      <mass value="0.022614240507152"/>
      <inertia ixx="1.52518312458174E-05" ixy="9.76583423954399E-10" ixz="-5.43838577022588E-10" iyy="6.17694243867776E-06" iyz="6.78636130740228E-06" izz="1.16494917907219E-05"/>
    </inertial>
    <visual>
      <origin rpy="0 0 0" xyz="0 0 0"/>
      <geometry>
        <mesh filename="package://robotiq_2f_85_gripper_visualization/meshes/visual/robotiq_arg2f_85_outer_finger.dae" scale="0.001 0.001 0.001"/>
      </geometry>
      <material name="">
        <color rgba="0.1 0.1 0.1 1"/>
      </material>
    </visual>
    <collision>
      <origin rpy="0 0 0" xyz="0 0 0"/>
      <geometry>
        <mesh filename="package://robotiq_2f_85_gripper_visualization/meshes/collision/robotiq_arg2f_85_outer_finger.dae" scale="0.001 0.001 0.001"/>
      </geometry>
    </collision>
  </link>
  <link name="left_inner_finger">
    <inertial>
      <origin rpy="0 0 0" xyz="0.000299999999999317 0.0160078233491243 -0.0136945669206257"/>
      <mass value="0.0104003125914103"/>
      <inertia ixx="2.71909453810972E-06" ixy="1.35402465472579E-21" ixz="-7.1817349065269E-22" iyy="7.69100314106116E-07" iyz="6.74715432769696E-07" izz="2.30315190420171E-06"/>
    </inertial>
    <visual>
      <origin rpy="0 0 0" xyz="0 0 0"/>
      <geometry>
        <mesh filename="package://robotiq_2f_85_gripper_visualization/meshes/visual/robotiq_arg2f_85_inner_finger.dae" scale="0.001 0.001 0.001"/>
      </geometry>
      <material name="">
        <color rgba="0.1 0.1 0.1 1"/>
      </material>
    </visual>
    <collision>
      <origin rpy="0 0 0" xyz="0 0 0"/>
      <geometry>
        <mesh filename="package://robotiq_2f_85_gripper_visualization/meshes/collision/robotiq_arg2f_85_inner_finger.dae" scale="0.001 0.001 0.001"/>
      </geometry>
    </collision>
  </link>
  <link name="left_inner_finger_pad">
    <visual>
      <origin rpy="0 0 0" xyz="0 0 0"/>
      <geometry>
        <box size="0.022 0.00635 0.0375"/>
      </geometry>
      <material name="">
        <color rgba="0.9 0.9 0.9 1"/>
      </material>
    </visual>
    <collision>
      <origin rpy="0 0 0" xyz="0 0 0"/>
      <geometry>
        <box size="0.022 0.00635 0.0375"/>
      </geometry>
      <material name="">
        <color rgba="0.9 0.0 0.0 1"/>
      </material>
    </collision>
  </link>
  <link name="left_inner_knuckle">
    <inertial>
      <origin rpy="0 0 0" xyz="0.000123011831763771 0.0507850843201817 0.00103968640075166"/>
      <mass value="0.0271177346495152"/>
      <inertia ixx="2.61910379223783E-05" ixy="-2.43616858946494E-07" ixz="-6.37789906117123E-09" iyy="2.8270243746167E-06" iyz="-5.37200748039765E-07" izz="2.83695868220296E-05"/>
    </inertial>
    <visual>
      <origin rpy="0 0 0" xyz="0 0 0"/>
      <geometry>
        <mesh filename="package://robotiq_2f_85_gripper_visualization/meshes/visual/robotiq_arg2f_85_inner_knuckle.dae" scale="0.001 0.001 0.001"/>
      </geometry>
      <material name="">
        <color rgba="0.1 0.1 0.1 1"/>
      </material>
    </visual>
    <collision>
      <origin rpy="0 0 0" xyz="0 0 0"/>
      <geometry>
        <mesh filename="package://robotiq_2f_85_gripper_visualization/meshes/collision/robotiq_arg2f_85_inner_knuckle.dae" scale="0.001 0.001 0.001"/>
      </geometry>
    </collision>
  </link>
  <link name="right_outer_knuckle">
    <inertial>
      <origin rpy="0 0 0" xyz="-0.000200000000003065 0.0199435877845359 0.0292245259211331"/>
      <mass value="0.00853198276973456"/>
      <inertia ixx="2.89328108496468E-06" ixy="-1.57935047237397E-19" ixz="-1.93980378593255E-19" iyy="1.86719750325683E-06" iyz="-1.21858577871576E-06" izz="1.21905238907251E-06"/>
    </inertial>
    <visual>
      <origin rpy="0 0 0" xyz="0 0 0"/>
      <geometry>
        <mesh filename="package://robotiq_2f_85_gripper_visualization/meshes/visual/robotiq_arg2f_85_outer_knuckle.dae" scale="0.001 0.001 0.001"/>
      </geometry>
      <material name="">
        <color rgba="0.792156862745098 0.819607843137255 0.933333333333333 1"/>
      </material>
    </visual>
    <collision>
      <origin rpy="0 0 0" xyz="0 0 0"/>
      <geometry>
        <mesh filename="package://robotiq_2f_85_gripper_visualization/meshes/collision/robotiq_arg2f_85_outer_knuckle.dae" scale="0.001 0.001 0.001"/>
      </geometry>
    </collision>
  </link>
  <link name="right_outer_finger">
    <inertial>
      <origin rpy="0 0 0" xyz="0.00030115855001899 0.0373907951953854 -0.0208027427000385"/>
      <mass value="0.022614240507152"/>
      <inertia ixx="1.52518312458174E-05" ixy="9.76583423954399E-10" ixz="-5.43838577022588E-10" iyy="6.17694243867776E-06" iyz="6.78636130740228E-06" izz="1.16494917907219E-05"/>
    </inertial>
    <visual>
      <origin rpy="0 0 0" xyz="0 0 0"/>
      <geometry>
        <mesh filename="package://robotiq_2f_85_gripper_visualization/meshes/visual/robotiq_arg2f_85_outer_finger.dae" scale="0.001 0.001 0.001"/>
      </geometry>
      <material name="">
        <color rgba="0.1 0.1 0.1 1"/>
      </material>
    </visual>
    <collision>
      <origin rpy="0 0 0" xyz="0 0 0"/>
      <geometry>
        <mesh filename="package://robotiq_2f_85_gripper_visualization/meshes/collision/robotiq_arg2f_85_outer_finger.dae" scale="0.001 0.001 0.001"/>
      </geometry>
    </collision>
  </link>
  <link name="right_inner_finger">
    <inertial>
      <origin rpy="0 0 0" xyz="0.000299999999999317 0.0160078233491243 -0.0136945669206257"/>
      <mass value="0.0104003125914103"/>
      <inertia ixx="2.71909453810972E-06" ixy="1.35402465472579E-21" ixz="-7.1817349065269E-22" iyy="7.69100314106116E-07" iyz="6.74715432769696E-07" izz="2.30315190420171E-06"/>
    </inertial>
    <visual>
      <origin rpy="0 0 0" xyz="0 0 0"/>
      <geometry>
        <mesh filename="package://robotiq_2f_85_gripper_visualization/meshes/visual/robotiq_arg2f_85_inner_finger.dae" scale="0.001 0.001 0.001"/>
      </geometry>
      <material name="">
        <color rgba="0.1 0.1 0.1 1"/>
      </material>
    </visual>
    <collision>
      <origin rpy="0 0 0" xyz="0 0 0"/>
      <geometry>
        <mesh filename="package://robotiq_2f_85_gripper_visualization/meshes/collision/robotiq_arg2f_85_inner_finger.dae" scale="0.001 0.001 0.001"/>
      </geometry>
    </collision>
  </link>
  <link name="right_inner_finger_pad">
    <visual>
      <origin rpy="0 0 0" xyz="0 0 0"/>
      <geometry>
        <box size="0.022 0.00635 0.0375"/>
      </geometry>
      <material name="">
        <color rgba="0.9 0.9 0.9 1"/>
      </material>
    </visual>
    <collision>
      <origin rpy="0 0 0" xyz="0 0 0"/>
      <geometry>
        <box size="0.022 0.00635 0.0375"/>
      </geometry>
      <material name="">
        <color rgba="0.9 0.0 0.0 1"/>
      </material>
    </collision>
  </link>
  <link name="right_inner_knuckle">
    <inertial>
      <origin rpy="0 0 0" xyz="0.000123011831763771 0.0507850843201817 0.00103968640075166"/>
      <mass value="0.0271177346495152"/>
      <inertia ixx="2.61910379223783E-05" ixy="-2.43616858946494E-07" ixz="-6.37789906117123E-09" iyy="2.8270243746167E-06" iyz="-5.37200748039765E-07" izz="2.83695868220296E-05"/>
    </inertial>
    <visual>
      <origin rpy="0 0 0" xyz="0 0 0"/>
      <geometry>
        <mesh filename="package://robotiq_2f_85_gripper_visualization/meshes/visual/robotiq_arg2f_85_inner_knuckle.dae" scale="0.001 0.001 0.001"/>
      </geometry>
      <material name="">
        <color rgba="0.1 0.1 0.1 1"/>
      </material>
    </visual>
    <collision>
      <origin rpy="0 0 0" xyz="0 0 0"/>
      <geometry>
        <mesh filename="package://robotiq_2f_85_gripper_visualization/meshes/collision/robotiq_arg2f_85_inner_knuckle.dae" scale="0.001 0.001 0.001"/>
      </geometry>
    </collision>
  </link>
  <joint name="finger_joint" type="fixed">
    <origin rpy="0 0 3.141592653589793" xyz="0 -0.0306011 0.054904"/>
    <parent link="robotiq_arg2f_base_link"/>
    <child link="left_outer_knuckle"/>
    <axis xyz="1 0 0"/>
    <limit effort="1000" lower="0" upper="0.8" velocity="2.0"/>
    <dynamics damping="0.1"/>
  </joint>
  <joint name="left_outer_finger_joint" type="fixed">
    <origin rpy="0 0 0" xyz="0 0.0315 -0.0041"/>
    <parent link="left_outer_knuckle"/>
    <child link="left_outer_finger"/>
    <axis xyz="1 0 0"/>
  </joint>
  <joint name="left_inner_knuckle_joint" type="fixed">
    <!-- <origin xyz="0 ${reflect * -0.0127} 0.06142" rpy="${pi / 2 + .725} 0 ${(reflect - 1) * pi / 2}" /> -->
    <origin rpy="0 0 3.141592653589793" xyz="0 -0.0127 0.06142"/>
    <parent link="robotiq_arg2f_base_link"/>
    <child link="left_inner_knuckle"/>
    <axis xyz="1 0 0"/>
    <limit effort="1000" lower="0" upper="0.8757" velocity="2.0"/>
    <mimic joint="finger_joint" multiplier="1" offset="0"/>
  </joint>
  <joint name="left_inner_finger_joint" type="fixed">
    <origin rpy="0 0 0" xyz="0 0.0061 0.0471"/>
    <parent link="left_outer_finger"/>
    <child link="left_inner_finger"/>
    <axis xyz="1 0 0"/>
    <limit effort="1000" lower="-0.8757" upper="0" velocity="2.0"/>
    <mimic joint="finger_joint" multiplier="-1" offset="0"/>
  </joint>
  <joint name="left_inner_finger_pad_joint" type="fixed">
    <origin rpy="0 0 0" xyz="0 -0.0220203446692936 0.03242"/>
    <parent link="left_inner_finger"/>
    <child link="left_inner_finger_pad"/>
    <axis xyz="0 0 1"/>
  </joint>
  <joint name="right_outer_knuckle_joint" type="fixed">
    <origin rpy="0 0 0" xyz="0 0.0306011 0.054904"/>
    <parent link="robotiq_arg2f_base_link"/>
    <child link="right_outer_knuckle"/>
    <axis xyz="1 0 0"/>
    <limit effort="1000" lower="0" upper="0.81" velocity="2.0"/>
    <mimic joint="finger_joint" multiplier="1" offset="0"/>
  </joint>
  <joint name="right_outer_finger_joint" type="fixed">
    <origin rpy="0 0 0" xyz="0 0.0315 -0.0041"/>
    <parent link="right_outer_knuckle"/>
    <child link="right_outer_finger"/>
    <axis xyz="1 0 0"/>
  </joint>
  <joint name="right_inner_knuckle_joint" type="fixed">
    <!-- <origin xyz="0 ${reflect * -0.0127} 0.06142" rpy="${pi / 2 + .725} 0 ${(reflect - 1) * pi / 2}" /> -->
    <origin rpy="0 0 0.0" xyz="0 0.0127 0.06142"/>
    <parent link="robotiq_arg2f_base_link"/>
    <child link="right_inner_knuckle"/>
    <axis xyz="1 0 0"/>
    <limit effort="1000" lower="0" upper="0.8757" velocity="2.0"/>
    <mimic joint="finger_joint" multiplier="1" offset="0"/>
  </joint>
  <joint name="right_inner_finger_joint" type="fixed">
    <origin rpy="0 0 0" xyz="0 0.0061 0.0471"/>
    <parent link="right_outer_finger"/>
    <child link="right_inner_finger"/>
    <axis xyz="1 0 0"/>
    <limit effort="1000" lower="-0.8757" upper="0" velocity="2.0"/>
    <mimic joint="finger_joint" multiplier="-1" offset="0"/>
  </joint>
  <joint name="right_inner_finger_pad_joint" type="fixed">
    <origin rpy="0 0 0" xyz="0 -0.0220203446692936 0.03242"/>
    <parent link="right_inner_finger"/>
    <child link="right_inner_finger_pad"/>
    <axis xyz="0 0 1"/>
  </joint>
  <transmission name="finger_joint_trans">
    <type>transmission_interface/SimpleTransmission</type>
    <joint name="finger_joint">
      <hardwareInterface>hardware_interface/PositionJointInterface</hardwareInterface>
    </joint>
    <actuator name="finger_joint_motor">
      <hardwareInterface>hardware_interface/PositionJointInterface</hardwareInterface>
      <mechanicalReduction>1</mechanicalReduction>
    </actuator>
  </transmission>
  <gazebo>
    <plugin filename="libroboticsgroup_gazebo_mimic_joint_plugin.so" name="mimic_robotiq_140_4">
      <joint>finger_joint</joint>
      <mimicJoint>right_outer_knuckle_joint</mimicJoint>
      <multiplier>-1.0</multiplier>
      <maxEffort>10.0</maxEffort>
    </plugin>
    <plugin filename="libroboticsgroup_gazebo_mimic_joint_plugin.so" name="mimic_robotiq_140_2">
      <joint>finger_joint</joint>
      <mimicJoint>left_inner_finger_joint</mimicJoint>
      <multiplier>1.0</multiplier>
      <maxEffort>10.0</maxEffort>
      <!--<offset>0.0</offset>-->
    </plugin>
    <plugin filename="libroboticsgroup_gazebo_mimic_joint_plugin.so" name="mimic_robotiq_140_1">
      <joint>finger_joint</joint>
      <mimicJoint>right_inner_finger_joint</mimicJoint>
      <multiplier>1.0</multiplier>
      <maxEffort>10.0</maxEffort>
    </plugin>
    <plugin filename="libroboticsgroup_gazebo_mimic_joint_plugin.so" name="mimic_robotiq_140_3">
      <joint>finger_joint</joint>
      <mimicJoint>left_inner_knuckle_joint</mimicJoint>
      <multiplier>-1.0</multiplier>
      <maxEffort>10.0</maxEffort>
    </plugin>
    <plugin filename="libroboticsgroup_gazebo_mimic_joint_plugin.so" name="mimic_robotiq_140_5">
      <joint>finger_joint</joint>
      <mimicJoint>right_inner_knuckle_joint</mimicJoint>
      <multiplier>-1.0</multiplier>
      <maxEffort>10.0</maxEffort>
    </plugin>
  </gazebo>
  <joint name="robotiq_flange_joint" type="fixed">
    <origin rpy="0 0 -0.523" xyz="0 0.0 0.0"/>
    <parent link="ee_link"/>
    <child link="robotiq_arg2f_base_link"/>
  </joint>
</robot>

